Workbook

Sheet Read Me
A1: Nordic Opportunity Pipeline – Read Me
A2: Assignment F-01 (with F-02 scoring) · Nordic Construction Company Ltd · Version 0.4 (multi-source scanner) · 24 Sep 2026
A4: Purpose | B4: One place to record every relevant tender, RFP, prequalification and EOI, screen it, score it (F-02) and feed Panel 3 of the MD Dashboard (F-03).
A5: Scope | B5: Building, civil, fit-out, renovation (and MEP for referral) valued from TZS 200 million upward. Consultancy-only tenders are out of scope.
A6: Sheets | B6: Pipeline – main register (Appendix F columns + helper columns) · Bid-NoBid – F-02 score per ID · Scoring Guide – gates, criteria, weights, thresholds · Friday Summary – counts and the 14-day due list · Panel 3 Feed – linked rows for the MD Dashboard · Watch List – banks and corporates without public tenders · Scan Log – what was checked and when · Lists – drop-down options.
A7: Colour code | B7: Blue text = type here. Black = formula, do not overwrite. Green = linked from another sheet. Yellow fill = settings (weights, thresholds, report date).
A8: Adding a tender | B8: Type the Tender no. in the next empty Pipeline row – the ID (OP-###) appears automatically and the row appears on Bid-NoBid and Panel 3 Feed. Fill the blue cells; use the drop-downs.
A9: 'NeST login needed' | B9: NeST shows only title, entity, dates and tender no. to the public. CRB class, estimated value, site visit and bid security are inside the tender document, visible after logging in with Nordic's NeST account (login details held by the QS Director, not in this file).
A10: Recommendation | B10: Shows 'Screen: Pursue / Check / Drop' (a first view from the notice) until all 12 criteria are scored on Bid-NoBid; then it shows Bid / Conditional (MD) / No-Bid.
A11: Alerts | B11: Deadline alert follows the Appendix E rule: RED if submission ≤ 7 days and status is not 'Preparing'; AMBER ≤ 14 days; GREEN beyond. Escalate to MD = value ≥ TZS 3bn, or deadline under 10 days with no MD decision yet (F-01 rules). JV tenders: escalate manually.
A12: Rule on numbers | B12: Never type an estimated value, CRB class or bid security that you have not read in the tender document or the PE's procurement plan. Leave blank or 'unverified'.
A13: Automatic feed | B13: The Tanzania Tender Scanner runs every 15 minutes on an office PC and checks: NeST (all Mainland public tenders), the World Bank's notices for Tanzania (civil works), the TANROADS website, the ZPPDA Zanzibar tender portal, and the CRDB and NMB tender pages. It keeps construction and civil-works tenders only, screens them, and adds new ones here with Found by = 'Auto-scan' and the source in the Source column. Others go to the Screened Out sheet. It updates deadlines that change at the source and writes a Scan Log line whenever it changes something. It only writes into empty rows – it never changes your scores, decisions or notes. While this file is open it cannot save, so close it when you finish; new tenders are added at the first scan after it is closed.
A14: Do not | B14: Do not insert or delete rows or columns on Pipeline or Bid-NoBid, and do not add pictures or charts to this file – the scanner cannot preserve pictures. Keep the file name and folder the same, or update scanner_config.json.
A15: Data in v0.1 | B15: 31 opportunities from the NeST Published Tenders list, read 24 Sep 2026 (326 published; 85 in Works). Watch list seeded with target clients from the programme and the Likong'o close-out report. Criterion 8 (location) pre-scored only; all other scores await evidence.

Sheet Pipeline
A1: Nordic Opportunity Pipeline
A2: F-01 · Appendix F layout · one row per tender, RFP, prequalification or EOI · blue = type here, black = formula · v0.3, 24 Sep 2026 · new tenders are added automatically every 15 minutes by the Tanzania Tender Scanner
A3: APPENDIX F COLUMNS | AA3: HELPER COLUMNS (screening, alerts, dashboard feed)
A4: ID | B4: Tender no. | C4: Date found | D4: Source | E4: Source URL | F4: Client | G4: Client type | H4: Tender title | I4: Scope summary | J4: Location | K4: Category | L4: CRB class required | M4: Est. value TZS | N4: Funding confirmed | O4: Site visit date | P4: Clarification deadline | Q4: Submission date | R4: Bid security | S4: Documents purchased | T4: Bid/No-Bid score | U4: Recommendation | V4: MD decision | W4: Status | X4: Owner | Y4: Outcome | Z4: Lessons | AA4: Date advertised | AB4: Notice type | AC4: Initial screen | AD4: Screen reason | AE4: Days to deadline | AF4: Deadline alert | AG4: Escalate to MD? | AH4: Win probability | AI4: Next action | AJ4: Found by | AK4: Source ID | AL4: Due-14 key
A5: =IF(B5="","","OP-"&TEXT(ROW()-4,"000")) | B5: 7205/2026/2027/W/09 | C5: 46289 | D5: NeST | E5: https://nest.go.tz/tenders/published-tenders | F5: City Council of Dodoma | G5: government | H5: Proposed construction of the City Council of Dodoma Head Office | I5: New multi-storey council head office building in Dodoma City | J5: Dodoma | K5: building | L5: NeST login needed | N5: unknown | O5: NeST login needed | P5: NeST login needed | Q5: 46303.417 | R5: NeST login needed | S5: N | T5: =IF(A5="","",IFERROR(INDEX('Bid-NoBid'!$T:$T,MATCH(A5,'Bid-NoBid'!$A:$A,0)),"")) | U5: =IF(A5="","",IFERROR(IF(OR(INDEX('Bid-NoBid'!$U:$U,MATCH(A5,'Bid-NoBid'!$A:$A,0))="",LEFT(INDEX('Bid-NoBid'!$U:$U,MATCH(A5,'Bid-NoBid'!$A:$A,0)),10)="Incomplete"),"Screen: "&AC5,INDEX('Bid-NoBid'!$U:$U,MATCH(A5,'Bid-NoBid'!$A:$A,0))),"Screen: "&AC5)) | W5: Watching | X5: Frank | AA5: 46288 | AB5: Small Works | AC5: Pursue | AD5: Flagship public building; 15-day window gives time to price; likely large value, so MD must see it | AE5: =IF(ISNUMBER(Q5),ROUNDDOWN(Q5-NOW(),1),"") | AF5: =IF(OR(A5="",AE5=""),"",IF(NOT(OR(W5="Watching",W5="Preparing")),"",IF(AE5<0,"PASSED",IF(AND(AE5<=7,W5<>"Preparing"),"RED",IF(AE5<=14,"AMBER","GREEN"))))) | AG5: =IF(OR(A5="",NOT(OR(W5="Watching",W5="Preparing"))),"",IF(AND(ISNUMBER(M5),M5>=3000000000),"YES – ≥ TZS 3bn",IF(AND(ISNUMBER(AE5),AE5>=0,AE5<10,V5=""),"YES – <10 days",""))) | AI5: Log in to NeST, download document, confirm CRB class, value and site visit; brief MD | AJ5: Manual scan | AK5: 36adabf5-6ac2-4a6b-bc14-a74e83964305 | AL5: =IF(AND(OR(W5="Watching",W5="Preparing"),ISNUMBER(Q5)),IF(AND(Q5>='Friday Summary'!$C$4,Q5<='Friday Summary'!$C$4+14),Q5+ROW()/1000000,""),"")
A6: =IF(B6="","","OP-"&TEXT(ROW()-4,"000")) | B6: TR33/2026/2027/W/01 | C6: 46289 | D6: NeST | E6: https://nest.go.tz/tenders/published-tenders | F6: President's Office – Ethics Secretariat | G6: government | H6: Proposed construction of office buildings and structures at Eastern Zonal Office (Morogoro) | I6: Office buildings and associated structures for the Eastern Zone office | J6: Morogoro | K6: building | L6: NeST login needed | N6: unknown | O6: NeST login needed | P6: NeST login needed | Q6: 46301.521 | R6: NeST login needed | S6: N | T6: =IF(A6="","",IFERROR(INDEX('Bid-NoBid'!$T:$T,MATCH(A6,'Bid-NoBid'!$A:$A,0)),"")) | U6: =IF(A6="","",IFERROR(IF(OR(INDEX('Bid-NoBid'!$U:$U,MATCH(A6,'Bid-NoBid'!$A:$A,0))="",LEFT(INDEX('Bid-NoBid'!$U:$U,MATCH(A6,'Bid-NoBid'!$A:$A,0)),10)="Incomplete"),"Screen: "&AC6,INDEX('Bid-NoBid'!$U:$U,MATCH(A6,'Bid-NoBid'!$A:$A,0))),"Screen: "&AC6)) | W6: Watching | X6: Frank | AA6: 46283 | AB6: Small Works | AC6: Pursue | AD6: Building works within reach of Dar; 11 days left | AE6: =IF(ISNUMBER(Q6),ROUNDDOWN(Q6-NOW(),1),"") | AF6: =IF(OR(A6="",AE6=""),"",IF(NOT(OR(W6="Watching",W6="Preparing")),"",IF(AE6<0,"PASSED",IF(AND(AE6<=7,W6<>"Preparing"),"RED",IF(AE6<=14,"AMBER","GREEN"))))) | AG6: =IF(OR(A6="",NOT(OR(W6="Watching",W6="Preparing"))),"",IF(AND(ISNUMBER(M6),M6>=3000000000),"YES – ≥ TZS 3bn",IF(AND(ISNUMBER(AE6),AE6>=0,AE6<10,V6=""),"YES – <10 days",""))) | AI6: Deadline changed at source 02-Oct (was 05-Oct 12:30). Download document; check CRB class and bid security | AJ6: Manual scan | AK6: 8021c469-1ab2-4f17-8090-49aee45b3951 | AL6: =IF(AND(OR(W6="Watching",W6="Preparing"),ISNUMBER(Q6)),IF(AND(Q6>='Friday Summary'!$C$4,Q6<='Friday Summary'!$C$4+14),Q6+ROW()/1000000,""),"")
A7: =IF(B7="","","OP-"&TEXT(ROW()-4,"000")) | B7: TR126/2026/2027/W/10 | C7: 46289 | D7: NeST | E7: https://nest.go.tz/tenders/published-tenders | F7: Tanzania Railways Corporation (TRC) | G7: parastatal | H7: Construction of running rooms and houses for TRC staff | I7: Staff housing and running rooms (locations per tender document) | J7: TBC – per tender document | K7: building | L7: NeST login needed | N7: unknown | O7: NeST login needed | P7: NeST login needed | Q7: 46301.583 | R7: NeST login needed | S7: N | T7: =IF(A7="","",IFERROR(INDEX('Bid-NoBid'!$T:$T,MATCH(A7,'Bid-NoBid'!$A:$A,0)),"")) | U7: =IF(A7="","",IFERROR(IF(OR(INDEX('Bid-NoBid'!$U:$U,MATCH(A7,'Bid-NoBid'!$A:$A,0))="",LEFT(INDEX('Bid-NoBid'!$U:$U,MATCH(A7,'Bid-NoBid'!$A:$A,0)),10)="Incomplete"),"Screen: "&AC7,INDEX('Bid-NoBid'!$U:$U,MATCH(A7,'Bid-NoBid'!$A:$A,0))),"Screen: "&AC7)) | W7: Watching | X7: Frank | AA7: 46281 | AB7: Small Works | AC7: Pursue | AD7: Repeat-able parastatal housing client; confirm site locations | AE7: =IF(ISNUMBER(Q7),ROUNDDOWN(Q7-NOW(),1),"") | AF7: =IF(OR(A7="",AE7=""),"",IF(NOT(OR(W7="Watching",W7="Preparing")),"",IF(AE7<0,"PASSED",IF(AND(AE7<=7,W7<>"Preparing"),"RED",IF(AE7<=14,"AMBER","GREEN"))))) | AG7: =IF(OR(A7="",NOT(OR(W7="Watching",W7="Preparing"))),"",IF(AND(ISNUMBER(M7),M7>=3000000000),"YES – ≥ TZS 3bn",IF(AND(ISNUMBER(AE7),AE7>=0,AE7<10,V7=""),"YES – <10 days",""))) | AI7: Deadline changed at source 03-Oct (was 02-Oct 14:00). Download document; confirm sites and number of lots | AJ7: Manual scan | AK7: e617135e-e227-4d65-9771-bd3210e77e15 | AL7: =IF(AND(OR(W7="Watching",W7="Preparing"),ISNUMBER(Q7)),IF(AND(Q7>='Friday Summary'!$C$4,Q7<='Friday Summary'!$C$4+14),Q7+ROW()/1000000,""),"")
A8: =IF(B8="","","OP-"&TEXT(ROW()-4,"000")) | B8: 99/2026/2027/W/03 | C8: 46289 | D8: NeST | E8: https://nest.go.tz/tenders/published-tenders | F8: Ministry of Livestock and Fisheries | G8: government | H8: Proposed rehabilitation of buildings and construction of fence at Vikuge Pasture Seed Farm, Kibaha | I8: Rehabilitation of existing buildings plus perimeter fence | J8: Pwani (Kibaha) | K8: renovation | L8: NeST login needed | N8: unknown | O8: NeST login needed | P8: NeST login needed | Q8: 46297.562 | R8: NeST login needed | S8: N | T8: =IF(A8="","",IFERROR(INDEX('Bid-NoBid'!$T:$T,MATCH(A8,'Bid-NoBid'!$A:$A,0)),"")) | U8: =IF(A8="","",IFERROR(IF(OR(INDEX('Bid-NoBid'!$U:$U,MATCH(A8,'Bid-NoBid'!$A:$A,0))="",LEFT(INDEX('Bid-NoBid'!$U:$U,MATCH(A8,'Bid-NoBid'!$A:$A,0)),10)="Incomplete"),"Screen: "&AC8,INDEX('Bid-NoBid'!$U:$U,MATCH(A8,'Bid-NoBid'!$A:$A,0))),"Screen: "&AC8)) | W8: Watching | X8: Frank | AA8: 46287 | AB8: Small Works | AC8: Pursue | AD8: Renovation close to Dar base; 8 days left | AE8: =IF(ISNUMBER(Q8),ROUNDDOWN(Q8-NOW(),1),"") | AF8: =IF(OR(A8="",AE8=""),"",IF(NOT(OR(W8="Watching",W8="Preparing")),"",IF(AE8<0,"PASSED",IF(AND(AE8<=7,W8<>"Preparing"),"RED",IF(AE8<=14,"AMBER","GREEN"))))) | AG8: =IF(OR(A8="",NOT(OR(W8="Watching",W8="Preparing"))),"",IF(AND(ISNUMBER(M8),M8>=3000000000),"YES – ≥ TZS 3bn",IF(AND(ISNUMBER(AE8),AE8>=0,AE8<10,V8=""),"YES – <10 days",""))) | AI8: Download document; arrange site visit to Kibaha | AJ8: Manual scan | AK8: 31809cbd-0353-49b1-b8e7-1fd8dcd63d06 | AL8: =IF(AND(OR(W8="Watching",W8="Preparing"),ISNUMBER(Q8)),IF(AND(Q8>='Friday Summary'!$C$4,Q8<='Friday Summary'!$C$4+14),Q8+ROW()/1000000,""),"")
A9: =IF(B9="","","OP-"&TEXT(ROW()-4,"000")) | B9: 71B8/2026/2027/W/10 | C9: 46289 | D9: NeST | E9: https://nest.go.tz/tenders/published-tenders | F9: Chalinze District Council | G9: government | H9: Proposed construction of Machinga Complex market | I9: New market complex for small traders | J9: Pwani (Chalinze) | K9: building | L9: NeST login needed | N9: unknown | O9: NeST login needed | P9: NeST login needed | Q9: 46295.583 | R9: NeST login needed | S9: N | T9: =IF(A9="","",IFERROR(INDEX('Bid-NoBid'!$T:$T,MATCH(A9,'Bid-NoBid'!$A:$A,0)),"")) | U9: =IF(A9="","",IFERROR(IF(OR(INDEX('Bid-NoBid'!$U:$U,MATCH(A9,'Bid-NoBid'!$A:$A,0))="",LEFT(INDEX('Bid-NoBid'!$U:$U,MATCH(A9,'Bid-NoBid'!$A:$A,0)),10)="Incomplete"),"Screen: "&AC9,INDEX('Bid-NoBid'!$U:$U,MATCH(A9,'Bid-NoBid'!$A:$A,0))),"Screen: "&AC9)) | W9: Watching | X9: Frank | AA9: 46288 | AB9: Small Works | AC9: Pursue | AD9: Building works in Coast region; 6 days left – needs fast decision | AE9: =IF(ISNUMBER(Q9),ROUNDDOWN(Q9-NOW(),1),"") | AF9: =IF(OR(A9="",AE9=""),"",IF(NOT(OR(W9="Watching",W9="Preparing")),"",IF(AE9<0,"PASSED",IF(AND(AE9<=7,W9<>"Preparing"),"RED",IF(AE9<=14,"AMBER","GREEN"))))) | AG9: =IF(OR(A9="",NOT(OR(W9="Watching",W9="Preparing"))),"",IF(AND(ISNUMBER(M9),M9>=3000000000),"YES – ≥ TZS 3bn",IF(AND(ISNUMBER(AE9),AE9>=0,AE9<10,V9=""),"YES – <10 days",""))) | AI9: MD decision by Fri 25 Sep; download document today | AJ9: Manual scan | AK9: bd92ae93-02c6-4dfb-955f-d3ecbbd943f6 | AL9: =IF(AND(OR(W9="Watching",W9="Preparing"),ISNUMBER(Q9)),IF(AND(Q9>='Friday Summary'!$C$4,Q9<='Friday Summary'!$C$4+14),Q9+ROW()/1000000,""),"")
A10: =IF(B10="","","OP-"&TEXT(ROW()-4,"000")) | B10: 3400/2026/2027/W/04 | C10: 46289 | D10: NeST | E10: https://nest.go.tz/tenders/published-tenders | F10: Tanzania Concrete Poles Manufacturing Co. Ltd | G10: parastatal (verify) | H10: Prequalification of building contractors | I10: Prequalification to a list of building contractors (no price) | J10: TBC | K10: building | L10: NeST login needed | N10: unknown | O10: NeST login needed | P10: NeST login needed | Q10: 46290.583 | R10: NeST login needed | S10: N | T10: =IF(A10="","",IFERROR(INDEX('Bid-NoBid'!$T:$T,MATCH(A10,'Bid-NoBid'!$A:$A,0)),"")) | U10: =IF(A10="","",IFERROR(IF(OR(INDEX('Bid-NoBid'!$U:$U,MATCH(A10,'Bid-NoBid'!$A:$A,0))="",LEFT(INDEX('Bid-NoBid'!$U:$U,MATCH(A10,'Bid-NoBid'!$A:$A,0)),10)="Incomplete"),"Screen: "&AC10,INDEX('Bid-NoBid'!$U:$U,MATCH(A10,'Bid-NoBid'!$A:$A,0))),"Screen: "&AC10)) | W10: Watching | X10: Frank | AA10: 46283 | AB10: Standard Invitation for Quotations -Works | AC10: Pursue | AD10: Low-cost prequalification – gets Nordic onto a client list; closes tomorrow | AE10: =IF(ISNUMBER(Q10),ROUNDDOWN(Q10-NOW(),1),"") | AF10: =IF(OR(A10="",AE10=""),"",IF(NOT(OR(W10="Watching",W10="Preparing")),"",IF(AE10<0,"PASSED",IF(AND(AE10<=7,W10<>"Preparing"),"RED",IF(AE10<=14,"AMBER","GREEN"))))) | AG10: =IF(OR(A10="",NOT(OR(W10="Watching",W10="Preparing"))),"",IF(AND(ISNUMBER(M10),M10>=3000000000),"YES – ≥ TZS 3bn",IF(AND(ISNUMBER(AE10),AE10>=0,AE10<10,V10=""),"YES – <10 days",""))) | AI10: Submit company documents on NeST by 25 Sep 14:00 if MD agrees | AJ10: Manual scan | AK10: 7fb06603-91ec-4823-8ca1-9d2f4716d07c | AL10: =IF(AND(OR(W10="Watching",W10="Preparing"),ISNUMBER(Q10)),IF(AND(Q10>='Friday Summary'!$C$4,Q10<='Friday Summary'!$C$4+14),Q10+ROW()/1000000,""),"")
A11: =IF(B11="","","OP-"&TEXT(ROW()-4,"000")) | B11: 88Z4/2026/2027/W/42 | C11: 46289 | D11: NeST | E11: https://nest.go.tz/tenders/published-tenders | F11: Ubungo Municipal Council | G11: government | H11: Completion of construction of two-storey building for 6 classrooms and ramp at Kawawa Primary School | I11: Completion works to two-storey classroom block | J11: Dar es Salaam (Ubungo) | K11: building | L11: NeST login needed | N11: unknown | O11: NeST login needed | P11: NeST login needed | Q11: 46290.583 | R11: NeST login needed | S11: N | T11: =IF(A11="","",IFERROR(INDEX('Bid-NoBid'!$T:$T,MATCH(A11,'Bid-NoBid'!$A:$A,0)),"")) | U11: =IF(A11="","",IFERROR(IF(OR(INDEX('Bid-NoBid'!$U:$U,MATCH(A11,'Bid-NoBid'!$A:$A,0))="",LEFT(INDEX('Bid-NoBid'!$U:$U,MATCH(A11,'Bid-NoBid'!$A:$A,0)),10)="Incomplete"),"Screen: "&AC11,INDEX('Bid-NoBid'!$U:$U,MATCH(A11,'Bid-NoBid'!$A:$A,0))),"Screen: "&AC11)) | W11: Watching | X11: Frank | AA11: 46283 | AB11: Small Works | AC11: Check | AD11: Dar location and school experience (Likong'o) fit, but closes tomorrow – likely too late | AE11: =IF(ISNUMBER(Q11),ROUNDDOWN(Q11-NOW(),1),"") | AF11: =IF(OR(A11="",AE11=""),"",IF(NOT(OR(W11="Watching",W11="Preparing")),"",IF(AE11<0,"PASSED",IF(AND(AE11<=7,W11<>"Preparing"),"RED",IF(AE11<=14,"AMBER","GREEN"))))) | AG11: =IF(OR(A11="",NOT(OR(W11="Watching",W11="Preparing"))),"",IF(AND(ISNUMBER(M11),M11>=3000000000),"YES – ≥ TZS 3bn",IF(AND(ISNUMBER(AE11),AE11>=0,AE11<10,V11=""),"YES – <10 days",""))) | AI11: Ask QS Director today whether a bid is possible by 25 Sep 14:00 | AJ11: Manual scan | AK11: cf629183-3fd7-4914-a528-58a55f549165 | AL11: =IF(AND(OR(W11="Watching",W11="Preparing"),ISNUMBER(Q11)),IF(AND(Q11>='Friday Summary'!$C$4,Q11<='Friday Summary'!$C$4+14),Q11+ROW()/1000000,""),"")
A12: =IF(B12="","","OP-"&TEXT(ROW()-4,"000")) | B12: 52/072/2026/2027/W/13 | C12: 46289 | D12: NeST | E12: https://nest.go.tz/tenders/published-tenders | F12: Temeke Regional Referral Hospital | G12: government | H12: Renovation of hospital blocks | I12: Renovation of hospital blocks (quotation) | J12: Dar es Salaam (Temeke) | K12: renovation | L12: NeST login needed | N12: unknown | O12: NeST login needed | P12: NeST login needed | Q12: 46295.583 | R12: NeST login needed | S12: N | T12: =IF(A12="","",IFERROR(INDEX('Bid-NoBid'!$T:$T,MATCH(A12,'Bid-NoBid'!$A:$A,0)),"")) | U12: =IF(A12="","",IFERROR(IF(OR(INDEX('Bid-NoBid'!$U:$U,MATCH(A12,'Bid-NoBid'!$A:$A,0))="",LEFT(INDEX('Bid-NoBid'!$U:$U,MATCH(A12,'Bid-NoBid'!$A:$A,0)),10)="Incomplete"),"Screen: "&AC12,INDEX('Bid-NoBid'!$U:$U,MATCH(A12,'Bid-NoBid'!$A:$A,0))),"Screen: "&AC12)) | W12: Watching | X12: Frank | AA12: 46288 | AB12: Standard Invitation for Quotations -Works | AC12: Check | AD12: Dar renovation, but quotation route suggests value may be under TZS 200m | AE12: =IF(ISNUMBER(Q12),ROUNDDOWN(Q12-NOW(),1),"") | AF12: =IF(OR(A12="",AE12=""),"",IF(NOT(OR(W12="Watching",W12="Preparing")),"",IF(AE12<0,"PASSED",IF(AND(AE12<=7,W12<>"Preparing"),"RED",IF(AE12<=14,"AMBER","GREEN"))))) | AG12: =IF(OR(A12="",NOT(OR(W12="Watching",W12="Preparing"))),"",IF(AND(ISNUMBER(M12),M12>=3000000000),"YES – ≥ TZS 3bn",IF(AND(ISNUMBER(AE12),AE12>=0,AE12<10,V12=""),"YES – <10 days",""))) | AI12: Download document; check scope size against TZS 200m threshold | AJ12: Manual scan | AK12: d18f9ef1-b72a-460d-b8f1-44ec5ee41c81 | AL12: =IF(AND(OR(W12="Watching",W12="Preparing"),ISNUMBER(Q12)),IF(AND(Q12>='Friday Summary'!$C$4,Q12<='Friday Summary'!$C$4+14),Q12+ROW()/1000000,""),"")
A13: =IF(B13="","","OP-"&TEXT(ROW()-4,"000")) | B13: 35/2026/2027/W/01 | C13: 46289 | D13: NeST | E13: https://nest.go.tz/tenders/published-tenders | F13: National Prosecutions Service (NPS) | G13: government | H13: Proposed construction of NPS Regional Office building at Mara, Plot 611 Block C, Bweri, Musoma | I13: New regional office building | J13: Mara (Musoma) | K13: building | L13: NeST login needed | N13: unknown | O13: NeST login needed | P13: NeST login needed | Q13: 46295.583 | R13: NeST login needed | S13: N | T13: =IF(A13="","",IFERROR(INDEX('Bid-NoBid'!$T:$T,MATCH(A13,'Bid-NoBid'!$A:$A,0)),"")) | U13: =IF(A13="","",IFERROR(IF(OR(INDEX('Bid-NoBid'!$U:$U,MATCH(A13,'Bid-NoBid'!$A:$A,0))="",LEFT(INDEX('Bid-NoBid'!$U:$U,MATCH(A13,'Bid-NoBid'!$A:$A,0)),10)="Incomplete"),"Screen: "&AC13,INDEX('Bid-NoBid'!$U:$U,MATCH(A13,'Bid-NoBid'!$A:$A,0))),"Screen: "&AC13)) | W13: Watching | X13: Frank | AA13: 46288 | AB13: Small Works | AC13: Check | AD13: Good building type but remote from Dar and only 6 days left | AE13: =IF(ISNUMBER(Q13),ROUNDDOWN(Q13-NOW(),1),"") | AF13: =IF(OR(A13="",AE13=""),"",IF(NOT(OR(W13="Watching",W13="Preparing")),"",IF(AE13<0,"PASSED",IF(AND(AE13<=7,W13<>"Preparing"),"RED",IF(AE13<=14,"AMBER","GREEN"))))) | AG13: =IF(OR(A13="",NOT(OR(W13="Watching",W13="Preparing"))),"",IF(AND(ISNUMBER(M13),M13>=3000000000),"YES – ≥ TZS 3bn",IF(AND(ISNUMBER(AE13),AE13>=0,AE13<10,V13=""),"YES – <10 days",""))) | AI13: Check CRB class and whether a Mwanza/Mara team is available | AJ13: Manual scan | AK13: 039aa3e3-4ce1-4bfd-b38a-5bf4743ab974 | AL13: =IF(AND(OR(W13="Watching",W13="Preparing"),ISNUMBER(Q13)),IF(AND(Q13>='Friday Summary'!$C$4,Q13<='Friday Summary'!$C$4+14),Q13+ROW()/1000000,""),"")
A14: =IF(B14="","","OP-"&TEXT(ROW()-4,"000")) | B14: 43/2026/2027/W/04 | C14: 46289 | D14: NeST | E14: https://nest.go.tz/tenders/published-tenders | F14: Ministry of Agriculture | G14: government | H14: Proposed construction and rehabilitation of infrastructure for thirteen (13) Youth Agribusiness Incubation Centres (YABICs) | I14: Construction/rehabilitation at 13 centres (multi-site) | J14: Multiple regions | K14: building | L14: NeST login needed | N14: unknown | O14: NeST login needed | P14: NeST login needed | Q14: 46295.583 | R14: NeST login needed | S14: N | T14: =IF(A14="","",IFERROR(INDEX('Bid-NoBid'!$T:$T,MATCH(A14,'Bid-NoBid'!$A:$A,0)),"")) | U14: =IF(A14="","",IFERROR(IF(OR(INDEX('Bid-NoBid'!$U:$U,MATCH(A14,'Bid-NoBid'!$A:$A,0))="",LEFT(INDEX('Bid-NoBid'!$U:$U,MATCH(A14,'Bid-NoBid'!$A:$A,0)),10)="Incomplete"),"Screen: "&AC14,INDEX('Bid-NoBid'!$U:$U,MATCH(A14,'Bid-NoBid'!$A:$A,0))),"Screen: "&AC14)) | W14: Watching | X14: Frank | AA14: 46287 | AB14: Small Works | AC14: Check | AD14: Multi-site programme – logistics risk; check lots and locations | AE14: =IF(ISNUMBER(Q14),ROUNDDOWN(Q14-NOW(),1),"") | AF14: =IF(OR(A14="",AE14=""),"",IF(NOT(OR(W14="Watching",W14="Preparing")),"",IF(AE14<0,"PASSED",IF(AND(AE14<=7,W14<>"Preparing"),"RED",IF(AE14<=14,"AMBER","GREEN"))))) | AG14: =IF(OR(A14="",NOT(OR(W14="Watching",W14="Preparing"))),"",IF(AND(ISNUMBER(M14),M14>=3000000000),"YES – ≥ TZS 3bn",IF(AND(ISNUMBER(AE14),AE14>=0,AE14<10,V14=""),"YES – <10 days",""))) | AI14: Download document; see if lots can be bid separately | AJ14: Manual scan | AK14: 0b80faa8-5fe7-4559-800e-4609f3668ee9 | AL14: =IF(AND(OR(W14="Watching",W14="Preparing"),ISNUMBER(Q14)),IF(AND(Q14>='Friday Summary'!$C$4,Q14<='Friday Summary'!$C$4+14),Q14+ROW()/1000000,""),"")
A15: =IF(B15="","","OP-"&TEXT(ROW()-4,"000")) | B15: 7512/2026/2027/W/10 | C15: 46289 | D15: NeST | E15: https://nest.go.tz/tenders/published-tenders | F15: Moshi Municipal Council | G15: government | H15: Proposed construction of new secondary school at Karanga Ward | I15: New secondary school | J15: Kilimanjaro (Moshi) | K15: building | L15: NeST login needed | N15: unknown | O15: NeST login needed | P15: NeST login needed | Q15: 46295.417 | R15: NeST login needed | S15: N | T15: =IF(A15="","",IFERROR(INDEX('Bid-NoBid'!$T:$T,MATCH(A15,'Bid-NoBid'!$A:$A,0)),"")) | U15: =IF(A15="","",IFERROR(IF(OR(INDEX('Bid-NoBid'!$U:$U,MATCH(A15,'Bid-NoBid'!$A:$A,0))="",LEFT(INDEX('Bid-NoBid'!$U:$U,MATCH(A15,'Bid-NoBid'!$A:$A,0)),10)="Incomplete"),"Screen: "&AC15,INDEX('Bid-NoBid'!$U:$U,MATCH(A15,'Bid-NoBid'!$A:$A,0))),"Screen: "&AC15)) | W15: Watching | X15: Frank | AA15: 46288 | AB15: Small Works | AC15: Check | AD15: School experience fits; remote and 6 days left | AE15: =IF(ISNUMBER(Q15),ROUNDDOWN(Q15-NOW(),1),"") | AF15: =IF(OR(A15="",AE15=""),"",IF(NOT(OR(W15="Watching",W15="Preparing")),"",IF(AE15<0,"PASSED",IF(AND(AE15<=7,W15<>"Preparing"),"RED",IF(AE15<=14,"AMBER","GREEN"))))) | AG15: =IF(OR(A15="",NOT(OR(W15="Watching",W15="Preparing"))),"",IF(AND(ISNUMBER(M15),M15>=3000000000),"YES – ≥ TZS 3bn",IF(AND(ISNUMBER(AE15),AE15>=0,AE15<10,V15=""),"YES – <10 days",""))) | AI15: Check value and CRB class | AJ15: Manual scan | AK15: 7af4f481-9db1-4a99-a2f9-2d33bb37d0cd | AL15: =IF(AND(OR(W15="Watching",W15="Preparing"),ISNUMBER(Q15)),IF(AND(Q15>='Friday Summary'!$C$4,Q15<='Friday Summary'!$C$4+14),Q15+ROW()/1000000,""),"")
A16: =IF(B16="","","OP-"&TEXT(ROW()-4,"000")) | B16: 75F4/2026/2027/W/16 | C16: 46289 | D16: NeST | E16: https://nest.go.tz/tenders/published-tenders | F16: Hai District Council | G16: government | H16: Renovation works at Sere Ufundi and Kware primary schools | I16: Renovation of two primary schools | J16: Kilimanjaro (Hai) | K16: renovation | L16: NeST login needed | N16: unknown | O16: NeST login needed | P16: NeST login needed | Q16: 46295.583 | R16: NeST login needed | S16: N | T16: =IF(A16="","",IFERROR(INDEX('Bid-NoBid'!$T:$T,MATCH(A16,'Bid-NoBid'!$A:$A,0)),"")) | U16: =IF(A16="","",IFERROR(IF(OR(INDEX('Bid-NoBid'!$U:$U,MATCH(A16,'Bid-NoBid'!$A:$A,0))="",LEFT(INDEX('Bid-NoBid'!$U:$U,MATCH(A16,'Bid-NoBid'!$A:$A,0)),10)="Incomplete"),"Screen: "&AC16,INDEX('Bid-NoBid'!$U:$U,MATCH(A16,'Bid-NoBid'!$A:$A,0))),"Screen: "&AC16)) | W16: Watching | X16: Frank | AA16: 46288 | AB16: Small Works | AC16: Drop | AD16: Likely small value and remote | AE16: =IF(ISNUMBER(Q16),ROUNDDOWN(Q16-NOW(),1),"") | AF16: =IF(OR(A16="",AE16=""),"",IF(NOT(OR(W16="Watching",W16="Preparing")),"",IF(AE16<0,"PASSED",IF(AND(AE16<=7,W16<>"Preparing"),"RED",IF(AE16<=14,"AMBER","GREEN"))))) | AG16: =IF(OR(A16="",NOT(OR(W16="Watching",W16="Preparing"))),"",IF(AND(ISNUMBER(M16),M16>=3000000000),"YES – ≥ TZS 3bn",IF(AND(ISNUMBER(AE16),AE16>=0,AE16<10,V16=""),"YES – <10 days",""))) | AI16: Record only | AJ16: Manual scan | AK16: 5ad50d18-a16f-48b2-a35f-d06ad3239815 | AL16: =IF(AND(OR(W16="Watching",W16="Preparing"),ISNUMBER(Q16)),IF(AND(Q16>='Friday Summary'!$C$4,Q16<='Friday Summary'!$C$4+14),Q16+ROW()/1000000,""),"")
... A34: =IF(B34="","","OP-"&TEXT(ROW()-4,"000")) | B34: TR36/2026/2027/W/15 | C34: 46289 | D34: NeST | E34: https://nest.go.tz/tenders/published-tenders | F34: TANROADS (HQ) | G34: government | H34: Upgrading of Mika–Utegi–Shitati–Ruari Port Road to bitumen standard – Lot 1: Mika–Utegi–Bukama (27 km) including Mori Bridge | I34: 27 km road upgrade to bitumen including bridge | J34: Mara (Rorya) | K34: civil | L34: NeST login needed | N34: unknown | O34: NeST login needed | P34: NeST login needed | Q34: 46297.583 | R34: NeST login needed | S34: N | T34: =IF(A34="","",IFERROR(INDEX('Bid-NoBid'!$T:$T,MATCH(A34,'Bid-NoBid'!$A:$A,0)),"")) | U34: =IF(A34="","",IFERROR(IF(OR(INDEX('Bid-NoBid'!$U:$U,MATCH(A34,'Bid-NoBid'!$A:$A,0))="",LEFT(INDEX('Bid-NoBid'!$U:$U,MATCH(A34,'Bid-NoBid'!$A:$A,0)),10)="Incomplete"),"Screen: "&AC34,INDEX('Bid-NoBid'!$U:$U,MATCH(A34,'Bid-NoBid'!$A:$A,0))),"Screen: "&AC34)) | W34: Watching | X34: Frank | AA34: 46267 | AB34: Medium and Large Works | AC34: Drop | AD34: Large road works likely above Civil Class IV; only possible in a JV (MD decision) | AE34: =IF(ISNUMBER(Q34),ROUNDDOWN(Q34-NOW(),1),"") | AF34: =IF(OR(A34="",AE34=""),"",IF(NOT(OR(W34="Watching",W34="Preparing")),"",IF(AE34<0,"PASSED",IF(AND(AE34<=7,W34<>"Preparing"),"RED",IF(AE34<=14,"AMBER","GREEN"))))) | AG34: =IF(OR(A34="",NOT(OR(W34="Watching",W34="Preparing"))),"",IF(AND(ISNUMBER(M34),M34>=3000000000),"YES – ≥ TZS 3bn",IF(AND(ISNUMBER(AE34),AE34>=0,AE34<10,V34=""),"YES – <10 days",""))) | AI34: Escalate to MD: JV interest? Otherwise no-bid | AJ34: Manual scan | AK34: 623047f2-016b-435d-9afa-348a5f8058c5 | AL34: =IF(AND(OR(W34="Watching",W34="Preparing"),ISNUMBER(Q34)),IF(AND(Q34>='Friday Summary'!$C$4,Q34<='Friday Summary'!$C$4+14),Q34+ROW()/1000000,""),"")
A35: =IF(B35="","","OP-"&TEXT(ROW()-4,"000")) | B35: 8626/2026/2027/W/15 | C35: 46289 | D35: NeST | E35: https://nest.go.tz/tenders/published-tenders | F35: Tanga City Council | G35: government | H35: Proposed construction of administration block at Nguvumali Secondary School | I35: New administration block (quotation) | J35: Tanga | K35: building | L35: NeST login needed | N35: unknown | O35: NeST login needed | P35: NeST login needed | Q35: 46289.417 | R35: NeST login needed | S35: N | T35: =IF(A35="","",IFERROR(INDEX('Bid-NoBid'!$T:$T,MATCH(A35,'Bid-NoBid'!$A:$A,0)),"")) | U35: =IF(A35="","",IFERROR(IF(OR(INDEX('Bid-NoBid'!$U:$U,MATCH(A35,'Bid-NoBid'!$A:$A,0))="",LEFT(INDEX('Bid-NoBid'!$U:$U,MATCH(A35,'Bid-NoBid'!$A:$A,0)),10)="Incomplete"),"Screen: "&AC35,INDEX('Bid-NoBid'!$U:$U,MATCH(A35,'Bid-NoBid'!$A:$A,0))),"Screen: "&AC35)) | W35: Closed – missed | X35: Frank | Y35: Not submitted | Z35: Advertised 17 Sep with a 7-day window, closed before the first scan. NeST works windows are often 7 days – scan Mon and Thu without fail. | AA35: 46282 | AB35: Standard Invitation for Quotations -Works | AC35: Drop | AD35: Deadline passed 24 Sep 10:00 before first scan – relevant because Nordic is active in Tanga | AE35: =IF(ISNUMBER(Q35),ROUNDDOWN(Q35-NOW(),1),"") | AF35: =IF(OR(A35="",AE35=""),"",IF(NOT(OR(W35="Watching",W35="Preparing")),"",IF(AE35<0,"PASSED",IF(AND(AE35<=7,W35<>"Preparing"),"RED",IF(AE35<=14,"AMBER","GREEN"))))) | AG35: =IF(OR(A35="",NOT(OR(W35="Watching",W35="Preparing"))),"",IF(AND(ISNUMBER(M35),M35>=3000000000),"YES – ≥ TZS 3bn",IF(AND(ISNUMBER(AE35),AE35>=0,AE35<10,V35=""),"YES – <10 days",""))) | AI35: None – see Lessons | AJ35: Manual scan | AK35: 436fa632-e675-47fa-b97e-9289a191bd3c | AL35: =IF(AND(OR(W35="Watching",W35="Preparing"),ISNUMBER(Q35)),IF(AND(Q35>='Friday Summary'!$C$4,Q35<='Friday Summary'!$C$4+14),Q35+ROW()/1000000,""),"")
A36: =IF(B36="","","OP-"&TEXT(ROW()-4,"000")) | B36: TR214/2026/2027/W/10 | C36: 46291 | D36: NeST | E36: https://nest.go.tz/tenders/published-tenders | F36: Tanzania Fertilizer Company | G36: parastatal (verify) | H36: Construction of Retaining wall pre-casted (Jersey Blocks) for blending facility | I36: From NeST notice (1 lot) – read the tender document | J36: Dar es Salaam (Ubungo) (from client's office – confirm site) | K36: building | L36: NeST login needed | N36: unknown | O36: NeST login needed | P36: NeST login needed | Q36: 46297.583 | R36: NeST login needed | S36: N | T36: =IF(A36="","",IFERROR(INDEX('Bid-NoBid'!$T:$T,MATCH(A36,'Bid-NoBid'!$A:$A,0)),"")) | U36: =IF(A36="","",IFERROR(IF(OR(INDEX('Bid-NoBid'!$U:$U,MATCH(A36,'Bid-NoBid'!$A:$A,0))="",LEFT(INDEX('Bid-NoBid'!$U:$U,MATCH(A36,'Bid-NoBid'!$A:$A,0)),10)="Incomplete"),"Screen: "&AC36,INDEX('Bid-NoBid'!$U:$U,MATCH(A36,'Bid-NoBid'!$A:$A,0))),"Screen: "&AC36)) | W36: Watching | X36: Frank | AA36: 46290 | AB36: Standard Invitation for Quotations -Works / Planned Tender | AC36: Check | AD36: Auto (Standard Invitation for Quotations -Works / Planned Tender): Quotation route – value may be below TZS 200m | AE36: =IF(ISNUMBER(Q36),ROUNDDOWN(Q36-NOW(),1),"") | AF36: =IF(OR(A36="",AE36=""),"",IF(NOT(OR(W36="Watching",W36="Preparing")),"",IF(AE36<0,"PASSED",IF(AND(AE36<=7,W36<>"Preparing"),"RED",IF(AE36<=14,"AMBER","GREEN"))))) | AG36: =IF(OR(A36="",NOT(OR(W36="Watching",W36="Preparing"))),"",IF(AND(ISNUMBER(M36),M36>=3000000000),"YES – ≥ TZS 3bn",IF(AND(ISNUMBER(AE36),AE36>=0,AE36<10,V36=""),"YES – <10 days",""))) | AI36: Read the notice and decide with the QS Director whether to pursue | AJ36: Auto-scan | AK36: 3759493a-b118-4946-b97b-da9c8bdfc677 | AL36: =IF(AND(OR(W36="Watching",W36="Preparing"),ISNUMBER(Q36)),IF(AND(Q36>='Friday Summary'!$C$4,Q36<='Friday Summary'!$C$4+14),Q36+ROW()/1000000,""),"")
A37: =IF(B37="","","OP-"&TEXT(ROW()-4,"000")) | B37: 83/2026/2027/W/08 | C37: 46291 | D37: NeST | E37: https://nest.go.tz/tenders/published-tenders | F37: Shinyanga Regional Secretariat | G37: government | H37: To rehabilitate Regional Commissioner's Office, Confidential Registry and residence house for Assistant Administrative secretaries. | I37: From NeST notice (1 lot) – read the tender document | J37: Shinyanga (from client's office – confirm site) | K37: building | L37: NeST login needed | N37: unknown | O37: NeST login needed | P37: NeST login needed | Q37: 46300.583 | R37: NeST login needed | S37: N | T37: =IF(A37="","",IFERROR(INDEX('Bid-NoBid'!$T:$T,MATCH(A37,'Bid-NoBid'!$A:$A,0)),"")) | U37: =IF(A37="","",IFERROR(IF(OR(INDEX('Bid-NoBid'!$U:$U,MATCH(A37,'Bid-NoBid'!$A:$A,0))="",LEFT(INDEX('Bid-NoBid'!$U:$U,MATCH(A37,'Bid-NoBid'!$A:$A,0)),10)="Incomplete"),"Screen: "&AC37,INDEX('Bid-NoBid'!$U:$U,MATCH(A37,'Bid-NoBid'!$A:$A,0))),"Screen: "&AC37)) | W37: Watching | X37: Frank | AA37: 46290 | AB37: Small Works / Tender | AC37: Check | AD37: Auto (Small Works / Tender): Building works but remote from Dar | AE37: =IF(ISNUMBER(Q37),ROUNDDOWN(Q37-NOW(),1),"") | AF37: =IF(OR(A37="",AE37=""),"",IF(NOT(OR(W37="Watching",W37="Preparing")),"",IF(AE37<0,"PASSED",IF(AND(AE37<=7,W37<>"Preparing"),"RED",IF(AE37<=14,"AMBER","GREEN"))))) | AG37: =IF(OR(A37="",NOT(OR(W37="Watching",W37="Preparing"))),"",IF(AND(ISNUMBER(M37),M37>=3000000000),"YES – ≥ TZS 3bn",IF(AND(ISNUMBER(AE37),AE37>=0,AE37<10,V37=""),"YES – <10 days",""))) | AI37: Read the notice and decide with the QS Director whether to pursue | AJ37: Auto-scan | AK37: 31257613-ab2c-4569-b096-277031c9bd9d | AL37: =IF(AND(OR(W37="Watching",W37="Preparing"),ISNUMBER(Q37)),IF(AND(Q37>='Friday Summary'!$C$4,Q37<='Friday Summary'!$C$4+14),Q37+ROW()/1000000,""),"")
A38: =IF(B38="","","OP-"&TEXT(ROW()-4,"000")) | B38: (not shown) | C38: 46291 | D38: press | E38: https://www.ddotenders.co.tz/tender.php?page=home | F38: High Commission of India | G38: government | H38: Maintenance of building and equipments | I38: From press notice (1 lot) – read the tender document | J38: Dar es Salaam | K38: building | L38: See tender document | N38: unknown | O38: See tender document | P38: See tender document | Q38: 46295.417 | R38: See tender document | S38: N | T38: =IF(A38="","",IFERROR(INDEX('Bid-NoBid'!$T:$T,MATCH(A38,'Bid-NoBid'!$A:$A,0)),"")) | U38: =IF(A38="","",IFERROR(IF(OR(INDEX('Bid-NoBid'!$U:$U,MATCH(A38,'Bid-NoBid'!$A:$A,0))="",LEFT(INDEX('Bid-NoBid'!$U:$U,MATCH(A38,'Bid-NoBid'!$A:$A,0)),10)="Incomplete"),"Screen: "&AC38,INDEX('Bid-NoBid'!$U:$U,MATCH(A38,'Bid-NoBid'!$A:$A,0))),"Screen: "&AC38)) | W38: Watching | X38: Frank | AA38: 46288 | AB38: DDO Tenders (newspaper / private / donor) | AC38: Pursue | AD38: Auto (DDO Tenders): Building works within reach of Dar · deadline read from the web page – confirm | AE38: =IF(ISNUMBER(Q38),ROUNDDOWN(Q38-NOW(),1),"") | AF38: =IF(OR(A38="",AE38=""),"",IF(NOT(OR(W38="Watching",W38="Preparing")),"",IF(AE38<0,"PASSED",IF(AND(AE38<=7,W38<>"Preparing"),"RED",IF(AE38<=14,"AMBER","GREEN"))))) | AG38: =IF(OR(A38="",NOT(OR(W38="Watching",W38="Preparing"))),"",IF(AND(ISNUMBER(M38),M38>=3000000000),"YES – ≥ TZS 3bn",IF(AND(ISNUMBER(AE38),AE38>=0,AE38<10,V38=""),"YES – <10 days",""))) | AI38: Get the tender document, confirm value, CRB class, site visit and bid security; brief the MD | AJ38: Auto-scan | AK38: DDO:3048 | AL38: =IF(AND(OR(W38="Watching",W38="Preparing"),ISNUMBER(Q38)),IF(AND(Q38>='Friday Summary'!$C$4,Q38<='Friday Summary'!$C$4+14),Q38+ROW()/1000000,""),"")
A39: =IF(B39="","","OP-"&TEXT(ROW()-4,"000")) | B39: GIZ/DTC/7000022671/2026 | C39: 46291 | D39: press | E39: https://www.ddotenders.co.tz/tender.php?page=home | F39: giz | G39: government | H39: Capacity building project | I39: From press notice (1 lot) – read the tender document | J39: Dar es Salaam | K39: building | L39: See tender document | N39: unknown | O39: See tender document | P39: See tender document | Q39: 46300.417 | R39: See tender document | S39: N | T39: =IF(A39="","",IFERROR(INDEX('Bid-NoBid'!$T:$T,MATCH(A39,'Bid-NoBid'!$A:$A,0)),"")) | U39: =IF(A39="","",IFERROR(IF(OR(INDEX('Bid-NoBid'!$U:$U,MATCH(A39,'Bid-NoBid'!$A:$A,0))="",LEFT(INDEX('Bid-NoBid'!$U:$U,MATCH(A39,'Bid-NoBid'!$A:$A,0)),10)="Incomplete"),"Screen: "&AC39,INDEX('Bid-NoBid'!$U:$U,MATCH(A39,'Bid-NoBid'!$A:$A,0))),"Screen: "&AC39)) | W39: Watching | X39: Frank | AA39: 46289 | AB39: DDO Tenders (newspaper / private / donor) | AC39: Pursue | AD39: Auto (DDO Tenders): Building works within reach of Dar · deadline read from the web page – confirm | AE39: =IF(ISNUMBER(Q39),ROUNDDOWN(Q39-NOW(),1),"") | AF39: =IF(OR(A39="",AE39=""),"",IF(NOT(OR(W39="Watching",W39="Preparing")),"",IF(AE39<0,"PASSED",IF(AND(AE39<=7,W39<>"Preparing"),"RED",IF(AE39<=14,"AMBER","GREEN"))))) | AG39: =IF(OR(A39="",NOT(OR(W39="Watching",W39="Preparing"))),"",IF(AND(ISNUMBER(M39),M39>=3000000000),"YES – ≥ TZS 3bn",IF(AND(ISNUMBER(AE39),AE39>=0,AE39<10,V39=""),"YES – <10 days",""))) | AI39: Get the tender document, confirm value, CRB class, site visit and bid security; brief the MD | AJ39: Auto-scan | AK39: DDO:3053 | AL39: =IF(AND(OR(W39="Watching",W39="Preparing"),ISNUMBER(Q39)),IF(AND(Q39>='Friday Summary'!$C$4,Q39<='Friday Summary'!$C$4+14),Q39+ROW()/1000000,""),"")
A40: =IF(B40="","","OP-"&TEXT(ROW()-4,"000")) | B40: TPL/2026/ENG/0010 | C40: 46291 | D40: press | E40: https://www.ddotenders.co.tz/tender.php?page=home | F40: See advert | G40: government | H40: Construction of toilets for police camps | I40: From press notice (1 lot) – read the tender document | J40: Dar es Salaam | K40: building | L40: See tender document | N40: unknown | O40: See tender document | P40: See tender document | Q40: 46304.417 | R40: See tender document | S40: N | T40: =IF(A40="","",IFERROR(INDEX('Bid-NoBid'!$T:$T,MATCH(A40,'Bid-NoBid'!$A:$A,0)),"")) | U40: =IF(A40="","",IFERROR(IF(OR(INDEX('Bid-NoBid'!$U:$U,MATCH(A40,'Bid-NoBid'!$A:$A,0))="",LEFT(INDEX('Bid-NoBid'!$U:$U,MATCH(A40,'Bid-NoBid'!$A:$A,0)),10)="Incomplete"),"Screen: "&AC40,INDEX('Bid-NoBid'!$U:$U,MATCH(A40,'Bid-NoBid'!$A:$A,0))),"Screen: "&AC40)) | W40: Watching | X40: Frank | AA40: 46288 | AB40: DDO Tenders (newspaper / private / donor) | AC40: Pursue | AD40: Auto (DDO Tenders): Building works within reach of Dar · deadline read from the web page – confirm | AE40: =IF(ISNUMBER(Q40),ROUNDDOWN(Q40-NOW(),1),"") | AF40: =IF(OR(A40="",AE40=""),"",IF(NOT(OR(W40="Watching",W40="Preparing")),"",IF(AE40<0,"PASSED",IF(AND(AE40<=7,W40<>"Preparing"),"RED",IF(AE40<=14,"AMBER","GREEN"))))) | AG40: =IF(OR(A40="",NOT(OR(W40="Watching",W40="Preparing"))),"",IF(AND(ISNUMBER(M40),M40>=3000000000),"YES – ≥ TZS 3bn",IF(AND(ISNUMBER(AE40),AE40>=0,AE40<10,V40=""),"YES – <10 days",""))) | AI40: Get the tender document, confirm value, CRB class, site visit and bid security; brief the MD | AJ40: Auto-scan | AK40: DDO:3050 | AL40: =IF(AND(OR(W40="Watching",W40="Preparing"),ISNUMBER(Q40)),IF(AND(Q40>='Friday Summary'!$C$4,Q40<='Friday Summary'!$C$4+14),Q40+ROW()/1000000,""),"")
A41: =IF(B41="","","OP-"&TEXT(ROW()-4,"000")) | B41: (not shown) | C41: 46291 | D41: press | E41: https://www.ddotenders.co.tz/tender.php?page=home | F41: TAZAMA Pipelines Limited | G41: parastatal (verify) | H41: Construction of Petroleum Pipeline | I41: From press notice (1 lot) – read the tender document | J41: Dar es Salaam | K41: civil | L41: See tender document | N41: unknown | O41: See tender document | P41: See tender document | Q41: 46318.417 | R41: See tender document | S41: N | T41: =IF(A41="","",IFERROR(INDEX('Bid-NoBid'!$T:$T,MATCH(A41,'Bid-NoBid'!$A:$A,0)),"")) | U41: =IF(A41="","",IFERROR(IF(OR(INDEX('Bid-NoBid'!$U:$U,MATCH(A41,'Bid-NoBid'!$A:$A,0))="",LEFT(INDEX('Bid-NoBid'!$U:$U,MATCH(A41,'Bid-NoBid'!$A:$A,0)),10)="Incomplete"),"Screen: "&AC41,INDEX('Bid-NoBid'!$U:$U,MATCH(A41,'Bid-NoBid'!$A:$A,0))),"Screen: "&AC41)) | W41: Watching | X41: Frank | AA41: 46281 | AB41: DDO Tenders (newspaper / private / donor) | AC41: Check | AD41: Auto (DDO Tenders): Civil works in Dar/Coast – confirm CRB class and margin · deadline read from the web page – confirm | AE41: =IF(ISNUMBER(Q41),ROUNDDOWN(Q41-NOW(),1),"") | AF41: =IF(OR(A41="",AE41=""),"",IF(NOT(OR(W41="Watching",W41="Preparing")),"",IF(AE41<0,"PASSED",IF(AND(AE41<=7,W41<>"Preparing"),"RED",IF(AE41<=14,"AMBER","GREEN"))))) | AG41: =IF(OR(A41="",NOT(OR(W41="Watching",W41="Preparing"))),"",IF(AND(ISNUMBER(M41),M41>=3000000000),"YES – ≥ TZS 3bn",IF(AND(ISNUMBER(AE41),AE41>=0,AE41<10,V41=""),"YES – <10 days",""))) | AI41: Read the notice and decide with the QS Director whether to pursue | AJ41: Auto-scan | AK41: DDO:3033 | AL41: =IF(AND(OR(W41="Watching",W41="Preparing"),ISNUMBER(Q41)),IF(AND(Q41>='Friday Summary'!$C$4,Q41<='Friday Summary'!$C$4+14),Q41+ROW()/1000000,""),"")
A42: =IF(B42="","","OP-"&TEXT(ROW()-4,"000")) | B42: 71B6/2026/2027/W/01 | C42: 46291 | D42: NeST | E42: https://nest.go.tz/tenders/published-tenders | F42: Mkuranga District Council | G42: government | H42: Proposed construction of One Market center for Entrepreneurship purposes at Mkuranga DC | I42: From NeST notice (1 lot) – read the tender document | J42: Pwani (Mkuranga) | K42: building | L42: NeST login needed | N42: unknown | O42: NeST login needed | P42: NeST login needed | Q42: 46297.417 | R42: NeST login needed | S42: N | T42: =IF(A42="","",IFERROR(INDEX('Bid-NoBid'!$T:$T,MATCH(A42,'Bid-NoBid'!$A:$A,0)),"")) | U42: =IF(A42="","",IFERROR(IF(OR(INDEX('Bid-NoBid'!$U:$U,MATCH(A42,'Bid-NoBid'!$A:$A,0))="",LEFT(INDEX('Bid-NoBid'!$U:$U,MATCH(A42,'Bid-NoBid'!$A:$A,0)),10)="Incomplete"),"Screen: "&AC42,INDEX('Bid-NoBid'!$U:$U,MATCH(A42,'Bid-NoBid'!$A:$A,0))),"Screen: "&AC42)) | W42: Watching | X42: Frank | AA42: 46290 | AB42: Small Works / Tender | AC42: Pursue | AD42: Auto (Small Works / Tender): Building works within reach of Dar | AE42: =IF(ISNUMBER(Q42),ROUNDDOWN(Q42-NOW(),1),"") | AF42: =IF(OR(A42="",AE42=""),"",IF(NOT(OR(W42="Watching",W42="Preparing")),"",IF(AE42<0,"PASSED",IF(AND(AE42<=7,W42<>"Preparing"),"RED",IF(AE42<=14,"AMBER","GREEN"))))) | AG42: =IF(OR(A42="",NOT(OR(W42="Watching",W42="Preparing"))),"",IF(AND(ISNUMBER(M42),M42>=3000000000),"YES – ≥ TZS 3bn",IF(AND(ISNUMBER(AE42),AE42>=0,AE42<10,V42=""),"YES – <10 days",""))) | AI42: Get the tender document, confirm value, CRB class, site visit and bid security; brief the MD | AJ42: Auto-scan | AK42: 81ede21a-8848-41d2-acc1-19a0f401563d | AL42: =IF(AND(OR(W42="Watching",W42="Preparing"),ISNUMBER(Q42)),IF(AND(Q42>='Friday Summary'!$C$4,Q42<='Friday Summary'!$C$4+14),Q42+ROW()/1000000,""),"")
A43: =IF(B43="","","OP-"&TEXT(ROW()-4,"000")) | B43: S10/001/2026/2027/W/33 | C43: 46292 | D43: NeST | E43: https://nest.go.tz/tenders/published-tenders | F43: TARURA - Arusha Regional Office | G43: government | H43: Construction of RC Bridge along Selela - Mbaash road | I43: From NeST notice (1 lot) – read the tender document | J43: Arusha (from client's office – confirm site) | K43: civil | L43: NeST login needed | N43: unknown | O43: NeST login needed | P43: NeST login needed | Q43: 46296.417 | R43: NeST login needed | S43: N | T43: =IF(A43="","",IFERROR(INDEX('Bid-NoBid'!$T:$T,MATCH(A43,'Bid-NoBid'!$A:$A,0)),"")) | U43: =IF(A43="","",IFERROR(IF(OR(INDEX('Bid-NoBid'!$U:$U,MATCH(A43,'Bid-NoBid'!$A:$A,0))="",LEFT(INDEX('Bid-NoBid'!$U:$U,MATCH(A43,'Bid-NoBid'!$A:$A,0)),10)="Incomplete"),"Screen: "&AC43,INDEX('Bid-NoBid'!$U:$U,MATCH(A43,'Bid-NoBid'!$A:$A,0))),"Screen: "&AC43)) | W43: Watching | X43: Frank | AA43: 46289 | AB43: Small Works / Tender | AC43: Check | AD43: Auto (Small Works / Tender): Construction tender kept for review (would have been dropped: Remote civil works) | AE43: =IF(ISNUMBER(Q43),ROUNDDOWN(Q43-NOW(),1),"") | AF43: =IF(OR(A43="",AE43=""),"",IF(NOT(OR(W43="Watching",W43="Preparing")),"",IF(AE43<0,"PASSED",IF(AND(AE43<=7,W43<>"Preparing"),"RED",IF(AE43<=14,"AMBER","GREEN"))))) | AG43: =IF(OR(A43="",NOT(OR(W43="Watching",W43="Preparing"))),"",IF(AND(ISNUMBER(M43),M43>=3000000000),"YES – ≥ TZS 3bn",IF(AND(ISNUMBER(AE43),AE43>=0,AE43<10,V43=""),"YES – <10 days",""))) | AI43: Read the notice and decide with the QS Director whether to pursue | AJ43: Auto-scan | AK43: 21d250d4-c78a-4692-b47e-c2aa6d201f38 | AL43: =IF(AND(OR(W43="Watching",W43="Preparing"),ISNUMBER(Q43)),IF(AND(Q43>='Friday Summary'!$C$4,Q43<='Friday Summary'!$C$4+14),Q43+ROW()/1000000,""),"")
A44: =IF(B44="","","OP-"&TEXT(ROW()-4,"000")) | B44: S10/025/2026/2027/W/69 | C44: 46292 | D44: NeST | E44: https://nest.go.tz/tenders/published-tenders | F44: TARURA - Tabora Regional Office | G44: government | H44: Periodic Maintenance Works 19.53km And Construction of 14 Box Culverts Along Simbo - Utuja - Uyui Border Road, Periodic Maintenance Works 12.67km And Construction of 6 Box Culverts Along Mwakadele - Chalamo Road and Periodic Maintenance Works 15km And Construction of 5 Box Culverts Along Igoweko - Simbo Road In Igunga District | I44: From NeST notice (1 lot) – read the tender document | J44: Tabora (Igunga) | K44: civil | L44: NeST login needed | N44: unknown | O44: NeST login needed | P44: NeST login needed | Q44: 46296.542 | R44: NeST login needed | S44: N | T44: =IF(A44="","",IFERROR(INDEX('Bid-NoBid'!$T:$T,MATCH(A44,'Bid-NoBid'!$A:$A,0)),"")) | U44: =IF(A44="","",IFERROR(IF(OR(INDEX('Bid-NoBid'!$U:$U,MATCH(A44,'Bid-NoBid'!$A:$A,0))="",LEFT(INDEX('Bid-NoBid'!$U:$U,MATCH(A44,'Bid-NoBid'!$A:$A,0)),10)="Incomplete"),"Screen: "&AC44,INDEX('Bid-NoBid'!$U:$U,MATCH(A44,'Bid-NoBid'!$A:$A,0))),"Screen: "&AC44)) | W44: Watching | X44: Frank | AA44: 46289 | AB44: Small Works / Tender | AC44: Check | AD44: Auto (Small Works / Tender): Construction tender kept for review (would have been dropped: Remote civil works) | AE44: =IF(ISNUMBER(Q44),ROUNDDOWN(Q44-NOW(),1),"") | AF44: =IF(OR(A44="",AE44=""),"",IF(NOT(OR(W44="Watching",W44="Preparing")),"",IF(AE44<0,"PASSED",IF(AND(AE44<=7,W44<>"Preparing"),"RED",IF(AE44<=14,"AMBER","GREEN"))))) | AG44: =IF(OR(A44="",NOT(OR(W44="Watching",W44="Preparing"))),"",IF(AND(ISNUMBER(M44),M44>=3000000000),"YES – ≥ TZS 3bn",IF(AND(ISNUMBER(AE44),AE44>=0,AE44<10,V44=""),"YES – <10 days",""))) | AI44: Read the notice and decide with the QS Director whether to pursue | AJ44: Auto-scan | AK44: 7f37e5d6-d2b8-40eb-ab77-6716c4186aef | AL44: =IF(AND(OR(W44="Watching",W44="Preparing"),ISNUMBER(Q44)),IF(AND(Q44>='Friday Summary'!$C$4,Q44<='Friday Summary'!$C$4+14),Q44+ROW()/1000000,""),"")
A45: =IF(B45="","","OP-"&TEXT(ROW()-4,"000")) | B45: TR219/003/2026/2027/W/08 | C45: 46292 | D45: NeST | E45: https://nest.go.tz/tenders/published-tenders | F45: TANAPA - Southern Zone | G45: government | H45: Construction of 400 Meters Long Boardwalk at Kitulo National Park | I45: From NeST notice (1 lot) – read the tender document | J45: Mbeya (Mbarali) (from client's office – confirm site) | K45: building | L45: NeST login needed | N45: unknown | O45: NeST login needed | P45: NeST login needed | Q45: 46297.583 | R45: NeST login needed | S45: N | T45: =IF(A45="","",IFERROR(INDEX('Bid-NoBid'!$T:$T,MATCH(A45,'Bid-NoBid'!$A:$A,0)),"")) | U45: =IF(A45="","",IFERROR(IF(OR(INDEX('Bid-NoBid'!$U:$U,MATCH(A45,'Bid-NoBid'!$A:$A,0))="",LEFT(INDEX('Bid-NoBid'!$U:$U,MATCH(A45,'Bid-NoBid'!$A:$A,0)),10)="Incomplete"),"Screen: "&AC45,INDEX('Bid-NoBid'!$U:$U,MATCH(A45,'Bid-NoBid'!$A:$A,0))),"Screen: "&AC45)) | W45: Watching | X45: Frank | AA45: 46290 | AB45: Standard Invitation for Quotations -Works / Planned Tender | AC45: Check | AD45: Auto (Standard Invitation for Quotations -Works / Planned Tender): Construction tender kept for review (would have been dropped: Remote and closing soon) | AE45: =IF(ISNUMBER(Q45),ROUNDDOWN(Q45-NOW(),1),"") | AF45: =IF(OR(A45="",AE45=""),"",IF(NOT(OR(W45="Watching",W45="Preparing")),"",IF(AE45<0,"PASSED",IF(AND(AE45<=7,W45<>"Preparing"),"RED",IF(AE45<=14,"AMBER","GREEN"))))) | AG45: =IF(OR(A45="",NOT(OR(W45="Watching",W45="Preparing"))),"",IF(AND(ISNUMBER(M45),M45>=3000000000),"YES – ≥ TZS 3bn",IF(AND(ISNUMBER(AE45),AE45>=0,AE45<10,V45=""),"YES – <10 days",""))) | AI45: Read the notice and decide with the QS Director whether to pursue | AJ45: Auto-scan | AK45: d2ae202b-08fd-4650-b448-193f5e653238 | AL45: =IF(AND(OR(W45="Watching",W45="Preparing"),ISNUMBER(Q45)),IF(AND(Q45>='Friday Summary'!$C$4,Q45<='Friday Summary'!$C$4+14),Q45+ROW()/1000000,""),"")
A46: =IF(B46="","","OP-"&TEXT(ROW()-4,"000")) | B46: TR36/001/2026/2027/W/48 | C46: 46292 | D46: NeST | E46: https://nest.go.tz/tenders/published-tenders | F46: TANROADS - Arusha Regional Office | G46: government | H46: Rehabilitation works of Karatu JCT - Mang'ola - Matala, Karatu Njiapanda - Matala, Makao Kimba - Matala Roads (Gravel Standard) and Construction of Drainage Structures at Njiapanda - Matala. | I46: From NeST notice (1 lot) – read the tender document | J46: Arusha (from client's office – confirm site) | K46: renovation | L46: NeST login needed | N46: unknown | O46: NeST login needed | P46: NeST login needed | Q46: 46297.583 | R46: NeST login needed | S46: N | T46: =IF(A46="","",IFERROR(INDEX('Bid-NoBid'!$T:$T,MATCH(A46,'Bid-NoBid'!$A:$A,0)),"")) | U46: =IF(A46="","",IFERROR(IF(OR(INDEX('Bid-NoBid'!$U:$U,MATCH(A46,'Bid-NoBid'!$A:$A,0))="",LEFT(INDEX('Bid-NoBid'!$U:$U,MATCH(A46,'Bid-NoBid'!$A:$A,0)),10)="Incomplete"),"Screen: "&AC46,INDEX('Bid-NoBid'!$U:$U,MATCH(A46,'Bid-NoBid'!$A:$A,0))),"Screen: "&AC46)) | W46: Watching | X46: Frank | AA46: 46290 | AB46: Small Works / Tender | AC46: Check | AD46: Auto (Small Works / Tender): Construction tender kept for review (would have been dropped: Remote and closing soon) | AE46: =IF(ISNUMBER(Q46),ROUNDDOWN(Q46-NOW(),1),"") | AF46: =IF(OR(A46="",AE46=""),"",IF(NOT(OR(W46="Watching",W46="Preparing")),"",IF(AE46<0,"PASSED",IF(AND(AE46<=7,W46<>"Preparing"),"RED",IF(AE46<=14,"AMBER","GREEN"))))) | AG46: =IF(OR(A46="",NOT(OR(W46="Watching",W46="Preparing"))),"",IF(AND(ISNUMBER(M46),M46>=3000000000),"YES – ≥ TZS 3bn",IF(AND(ISNUMBER(AE46),AE46>=0,AE46<10,V46=""),"YES – <10 days",""))) | AI46: Read the notice and decide with the QS Director whether to pursue | AJ46: Auto-scan | AK46: 215bdca8-8314-4274-892b-08df2a6cd22e | AL46: =IF(AND(OR(W46="Watching",W46="Preparing"),ISNUMBER(Q46)),IF(AND(Q46>='Friday Summary'!$C$4,Q46<='Friday Summary'!$C$4+14),Q46+ROW()/1000000,""),"")
A47: =IF(B47="","","OP-"&TEXT(ROW()-4,"000")) | B47: S10/074/2026/2027/W/56 | C47: 46292 | D47: NeST | E47: https://nest.go.tz/tenders/published-tenders | F47: TARURA - Kigoma Regional Office | G47: government | H47: Construction of Box Culvert at Ruzuguma River Along Mlati - Kagongo Road in Kigoma DC | I47: From NeST notice (1 lot) – read the tender document | J47: Kigoma | K47: civil | L47: NeST login needed | N47: unknown | O47: NeST login needed | P47: NeST login needed | Q47: 46297.583 | R47: NeST login needed | S47: N | T47: =IF(A47="","",IFERROR(INDEX('Bid-NoBid'!$T:$T,MATCH(A47,'Bid-NoBid'!$A:$A,0)),"")) | U47: =IF(A47="","",IFERROR(IF(OR(INDEX('Bid-NoBid'!$U:$U,MATCH(A47,'Bid-NoBid'!$A:$A,0))="",LEFT(INDEX('Bid-NoBid'!$U:$U,MATCH(A47,'Bid-NoBid'!$A:$A,0)),10)="Incomplete"),"Screen: "&AC47,INDEX('Bid-NoBid'!$U:$U,MATCH(A47,'Bid-NoBid'!$A:$A,0))),"Screen: "&AC47)) | W47: Watching | X47: Frank | AA47: 46290 | AB47: Small Works / Tender | AC47: Check | AD47: Auto (Small Works / Tender): Construction tender kept for review (would have been dropped: Remote civil works) | AE47: =IF(ISNUMBER(Q47),ROUNDDOWN(Q47-NOW(),1),"") | AF47: =IF(OR(A47="",AE47=""),"",IF(NOT(OR(W47="Watching",W47="Preparing")),"",IF(AE47<0,"PASSED",IF(AND(AE47<=7,W47<>"Preparing"),"RED",IF(AE47<=14,"AMBER","GREEN"))))) | AG47: =IF(OR(A47="",NOT(OR(W47="Watching",W47="Preparing"))),"",IF(AND(ISNUMBER(M47),M47>=3000000000),"YES – ≥ TZS 3bn",IF(AND(ISNUMBER(AE47),AE47>=0,AE47<10,V47=""),"YES – <10 days",""))) | AI47: Read the notice and decide with the QS Director whether to pursue | AJ47: Auto-scan | AK47: 2b7dd442-571f-46df-9686-9e5e50c548f5 | AL47: =IF(AND(OR(W47="Watching",W47="Preparing"),ISNUMBER(Q47)),IF(AND(Q47>='Friday Summary'!$C$4,Q47<='Friday Summary'!$C$4+14),Q47+ROW()/1000000,""),"")
... A59: =IF(B59="","","OP-"&TEXT(ROW()-4,"000")) | B59: TR36/008/2026/2027/W/42 | C59: 46296 | D59: NeST | E59: https://nest.go.tz/tenders/published-tenders | F59: TANROADS - Kigoma Regional Office | G59: government | H59: Construction Box Culvert and Catchwater Drain along Kigoma - Ujiji Paved Trunk Road | I59: From NeST notice (1 lot) – read the tender document | J59: Kigoma | K59: civil | L59: NeST login needed | N59: unknown | O59: NeST login needed | P59: NeST login needed | Q59: 46303.583 | R59: NeST login needed | S59: N | T59: =IF(A59="","",IFERROR(INDEX('Bid-NoBid'!$T:$T,MATCH(A59,'Bid-NoBid'!$A:$A,0)),"")) | U59: =IF(A59="","",IFERROR(IF(OR(INDEX('Bid-NoBid'!$U:$U,MATCH(A59,'Bid-NoBid'!$A:$A,0))="",LEFT(INDEX('Bid-NoBid'!$U:$U,MATCH(A59,'Bid-NoBid'!$A:$A,0)),10)="Incomplete"),"Screen: "&AC59,INDEX('Bid-NoBid'!$U:$U,MATCH(A59,'Bid-NoBid'!$A:$A,0))),"Screen: "&AC59)) | W59: Watching | X59: Frank | AA59: 46296 | AB59: Small Works / Tender | AC59: Check | AD59: Auto (Small Works / Tender): Construction tender kept for review (would have been dropped: Remote civil works) | AE59: =IF(ISNUMBER(Q59),ROUNDDOWN(Q59-NOW(),1),"") | AF59: =IF(OR(A59="",AE59=""),"",IF(NOT(OR(W59="Watching",W59="Preparing")),"",IF(AE59<0,"PASSED",IF(AND(AE59<=7,W59<>"Preparing"),"RED",IF(AE59<=14,"AMBER","GREEN"))))) | AG59: =IF(OR(A59="",NOT(OR(W59="Watching",W59="Preparing"))),"",IF(AND(ISNUMBER(M59),M59>=3000000000),"YES – ≥ TZS 3bn",IF(AND(ISNUMBER(AE59),AE59>=0,AE59<10,V59=""),"YES – <10 days",""))) | AI59: Read the notice and decide with the QS Director whether to pursue | AJ59: Auto-scan | AK59: 2ecad80f-1cb6-40a7-8d62-4ada928b9c16 | AL59: =IF(AND(OR(W59="Watching",W59="Preparing"),ISNUMBER(Q59)),IF(AND(Q59>='Friday Summary'!$C$4,Q59<='Friday Summary'!$C$4+14),Q59+ROW()/1000000,""),"")
A60: =IF(B60="","","OP-"&TEXT(ROW()-4,"000")) | B60: (not shown) | C60: 46296 | D60: press | E60: https://www.tanzaniatenders.com/tender/usambazaji-na-ufungaji-wa-milango-ya-mbao-katika-ujenzi-wa-ofisi-za-tarafa-zoisa-makang-wa-kibakwe-8f3c6e5.php | F60: See advert | G60: government | H60: Usambazaji Na Ufungaji Wa Milango Ya Mbao Katika Ujenzi Wa Ofisi Za Tarafa Zoisa, Makang'wa, Kibakwe, Mundemu, Pahi Na Goima | I60: From press notice (1 lot) – read the tender document | J60: Not stated – read the notice | K60: building | L60: See tender document | N60: unknown | O60: See tender document | P60: See tender document | Q60: 46303.417 | R60: See tender document | S60: N | T60: =IF(A60="","",IFERROR(INDEX('Bid-NoBid'!$T:$T,MATCH(A60,'Bid-NoBid'!$A:$A,0)),"")) | U60: =IF(A60="","",IFERROR(IF(OR(INDEX('Bid-NoBid'!$U:$U,MATCH(A60,'Bid-NoBid'!$A:$A,0))="",LEFT(INDEX('Bid-NoBid'!$U:$U,MATCH(A60,'Bid-NoBid'!$A:$A,0)),10)="Incomplete"),"Screen: "&AC60,INDEX('Bid-NoBid'!$U:$U,MATCH(A60,'Bid-NoBid'!$A:$A,0))),"Screen: "&AC60)) | W60: Watching | X60: Frank | AB60: TanzaniaTenders.com (newspapers / portals / private) | AC60: Check | AD60: Auto (TanzaniaTenders.com): Site not stated in the listing – read the notice · deadline read from the web page – confirm | AE60: =IF(ISNUMBER(Q60),ROUNDDOWN(Q60-NOW(),1),"") | AF60: =IF(OR(A60="",AE60=""),"",IF(NOT(OR(W60="Watching",W60="Preparing")),"",IF(AE60<0,"PASSED",IF(AND(AE60<=7,W60<>"Preparing"),"RED",IF(AE60<=14,"AMBER","GREEN"))))) | AG60: =IF(OR(A60="",NOT(OR(W60="Watching",W60="Preparing"))),"",IF(AND(ISNUMBER(M60),M60>=3000000000),"YES – ≥ TZS 3bn",IF(AND(ISNUMBER(AE60),AE60>=0,AE60<10,V60=""),"YES – <10 days",""))) | AI60: Read the notice and decide with the QS Director whether to pursue | AJ60: Auto-scan | AK60: TZT:150193893 | AL60: =IF(AND(OR(W60="Watching",W60="Preparing"),ISNUMBER(Q60)),IF(AND(Q60>='Friday Summary'!$C$4,Q60<='Friday Summary'!$C$4+14),Q60+ROW()/1000000,""),"")
A61: =IF(B61="","","OP-"&TEXT(ROW()-4,"000")) | B61: (not shown) | C61: 46296 | D61: press | E61: https://www.tanzaniatenders.com/tender/tza23002-10012-construction-materials-kidyama-water-supply-scheme-8f33822.php | F61: See advert | G61: government | H61: Tza23002-10012 - Construction Materials for Kidyama Water Supply Scheme | I61: From press notice (1 lot) – read the tender document | J61: Not stated – read the notice | K61: civil | L61: See tender document | N61: unknown | O61: See tender document | P61: See tender document | Q61: 46311.417 | R61: See tender document | S61: N | T61: =IF(A61="","",IFERROR(INDEX('Bid-NoBid'!$T:$T,MATCH(A61,'Bid-NoBid'!$A:$A,0)),"")) | U61: =IF(A61="","",IFERROR(IF(OR(INDEX('Bid-NoBid'!$U:$U,MATCH(A61,'Bid-NoBid'!$A:$A,0))="",LEFT(INDEX('Bid-NoBid'!$U:$U,MATCH(A61,'Bid-NoBid'!$A:$A,0)),10)="Incomplete"),"Screen: "&AC61,INDEX('Bid-NoBid'!$U:$U,MATCH(A61,'Bid-NoBid'!$A:$A,0))),"Screen: "&AC61)) | W61: Watching | X61: Frank | AB61: TanzaniaTenders.com (newspapers / portals / private) | AC61: Check | AD61: Auto (TanzaniaTenders.com): Civil works – confirm site, CRB class and margin · deadline read from the web page – confirm | AE61: =IF(ISNUMBER(Q61),ROUNDDOWN(Q61-NOW(),1),"") | AF61: =IF(OR(A61="",AE61=""),"",IF(NOT(OR(W61="Watching",W61="Preparing")),"",IF(AE61<0,"PASSED",IF(AND(AE61<=7,W61<>"Preparing"),"RED",IF(AE61<=14,"AMBER","GREEN"))))) | AG61: =IF(OR(A61="",NOT(OR(W61="Watching",W61="Preparing"))),"",IF(AND(ISNUMBER(M61),M61>=3000000000),"YES – ≥ TZS 3bn",IF(AND(ISNUMBER(AE61),AE61>=0,AE61<10,V61=""),"YES – <10 days",""))) | AI61: Read the notice and decide with the QS Director whether to pursue | AJ61: Auto-scan | AK61: TZT:150157346 | AL61: =IF(AND(OR(W61="Watching",W61="Preparing"),ISNUMBER(Q61)),IF(AND(Q61>='Friday Summary'!$C$4,Q61<='Friday Summary'!$C$4+14),Q61+ROW()/1000000,""),"")
A62: =IF(B62="","","OP-"&TEXT(ROW()-4,"000")) | B62: 52/063/2026/2027/W/03 | C62: 46297 | D62: NeST | E62: https://nest.go.tz/tenders/published-tenders | F62: Sokoine Regional Referral Hospital (lindi) | G62: government | H62: Proposed construction of Oxygen Plant Building at Sokoine Regional Referral Hospital - Lindi | I62: From NeST notice (1 lot) – read the tender document | J62: Lindi | K62: building | L62: NeST login needed | N62: unknown | O62: NeST login needed | P62: NeST login needed | Q62: 46303.583 | R62: NeST login needed | S62: N | T62: =IF(A62="","",IFERROR(INDEX('Bid-NoBid'!$T:$T,MATCH(A62,'Bid-NoBid'!$A:$A,0)),"")) | U62: =IF(A62="","",IFERROR(IF(OR(INDEX('Bid-NoBid'!$U:$U,MATCH(A62,'Bid-NoBid'!$A:$A,0))="",LEFT(INDEX('Bid-NoBid'!$U:$U,MATCH(A62,'Bid-NoBid'!$A:$A,0)),10)="Incomplete"),"Screen: "&AC62,INDEX('Bid-NoBid'!$U:$U,MATCH(A62,'Bid-NoBid'!$A:$A,0))),"Screen: "&AC62)) | W62: Watching | X62: Frank | AA62: 46296 | AB62: Small Works / Tender | AC62: Check | AD62: Auto (Small Works / Tender): Lindi/Mtwara – Nordic has worked there (Likong'o) | AE62: =IF(ISNUMBER(Q62),ROUNDDOWN(Q62-NOW(),1),"") | AF62: =IF(OR(A62="",AE62=""),"",IF(NOT(OR(W62="Watching",W62="Preparing")),"",IF(AE62<0,"PASSED",IF(AND(AE62<=7,W62<>"Preparing"),"RED",IF(AE62<=14,"AMBER","GREEN"))))) | AG62: =IF(OR(A62="",NOT(OR(W62="Watching",W62="Preparing"))),"",IF(AND(ISNUMBER(M62),M62>=3000000000),"YES – ≥ TZS 3bn",IF(AND(ISNUMBER(AE62),AE62>=0,AE62<10,V62=""),"YES – <10 days",""))) | AI62: Read the notice and decide with the QS Director whether to pursue | AJ62: Auto-scan | AK62: 1f05d8e5-1e65-4474-b335-be9236a50eca | AL62: =IF(AND(OR(W62="Watching",W62="Preparing"),ISNUMBER(Q62)),IF(AND(Q62>='Friday Summary'!$C$4,Q62<='Friday Summary'!$C$4+14),Q62+ROW()/1000000,""),"")
